Workbook

Sheet Dashboard
A1: Mirsad - Operations KPI Dashboard (Excel)
A2: March - May 2025 | AED | Gulf Standard Time | synthetic data (fictional client)
A3: KPI | B3: Value
A4: Tickets | B4: =COUNTA(Data_Tickets!$A$2:$A$2071) -> 2070
A5: Resolved | B5: =COUNT(Data_Tickets!$L$2:$L$2071) -> 1847
A6: Resolution rate | B6: =B5/B4 -> 0.89227053
A7: Median clearance velocity (working h) | B7: =MEDIAN(Data_Tickets!$L$2:$L$2071) -> 18.08
A8: Net variance (AED) | B8: =SUM(Data_Tickets!$I$2:$I$2071) -> -1526.25
A9: Margin variance vs budget | B9: =(SUM(Team_Month!C2:C19)-SUM(Team_Month!D2:D19))/SUM(Team_Month!D2:D19) -> 0.0074327579
A10: Resource utilization | B10: =SUM(Utilization!E2:E19)/SUM(Utilization!D2:D19) -> 0.80607966
A13: By team
A14: Team | B14: Tickets | C14: Median clearance (working h) | D14: Net variance AED | E14: Actual margin AED | F14: Budget margin AED | G14: Margin var % | H14: Utilization %
A15: FIN-OPS | B15: =COUNTIFS(Data_Tickets!$C$2:$C$2071,A15) -> 268 | C15: {=MEDIAN(IF((Data_Tickets!$C$2:$C$2071=A15)*ISNUMBER(Data_Tickets!$L$2:$L$2071),Data_Tickets!$L$2:$L$2071))} -> 15.46 | D15: =SUMIFS(Data_Tickets!$I$2:$I$2071,Data_Tickets!$C$2:$C$2071,A15) -> -423.77 | E15: =SUMIFS(Team_Month!C:C,Team_Month!A:A,A15) -> 21852 | F15: =SUMIFS(Team_Month!D:D,Team_Month!A:A,A15) -> 22900 | G15: =(E15-F15)/F15 -> -0.045764192 | H15: =SUMIFS(Utilization!E:E,Utilization!A:A,A15)/SUMIFS(Utilization!D:D,Utilization!A:A,A15) -> 0.84986772
A16: PAY-OPS | B16: =COUNTIFS(Data_Tickets!$C$2:$C$2071,A16) -> 345 | C16: {=MEDIAN(IF((Data_Tickets!$C$2:$C$2071=A16)*ISNUMBER(Data_Tickets!$L$2:$L$2071),Data_Tickets!$L$2:$L$2071))} -> 20.1 | D16: =SUMIFS(Data_Tickets!$I$2:$I$2071,Data_Tickets!$C$2:$C$2071,A16) -> 53.98 | E16: =SUMIFS(Team_Month!C:C,Team_Month!A:A,A16) -> 30298.5 | F16: =SUMIFS(Team_Month!D:D,Team_Month!A:A,A16) -> 30900 | G16: =(E16-F16)/F16 -> -0.019466019 | H16: =SUMIFS(Utilization!E:E,Utilization!A:A,A16)/SUMIFS(Utilization!D:D,Utilization!A:A,A16) -> 0.73611111
A17: CS-DXB | B17: =COUNTIFS(Data_Tickets!$C$2:$C$2071,A17) -> 446 | C17: {=MEDIAN(IF((Data_Tickets!$C$2:$C$2071=A17)*ISNUMBER(Data_Tickets!$L$2:$L$2071),Data_Tickets!$L$2:$L$2071))} -> 13.45 | D17: =SUMIFS(Data_Tickets!$I$2:$I$2071,Data_Tickets!$C$2:$C$2071,A17) -> -685.03 | E17: =SUMIFS(Team_Month!C:C,Team_Month!A:A,A17) -> 49040.1 | F17: =SUMIFS(Team_Month!D:D,Team_Month!A:A,A17) -> 50200 | G17: =(E17-F17)/F17 -> -0.023105578 | H17: =SUMIFS(Utilization!E:E,Utilization!A:A,A17)/SUMIFS(Utilization!D:D,Utilization!A:A,A17) -> 0.82420635
A18: CS-AUH | B18: =COUNTIFS(Data_Tickets!$C$2:$C$2071,A18) -> 232 | C18: {=MEDIAN(IF((Data_Tickets!$C$2:$C$2071=A18)*ISNUMBER(Data_Tickets!$L$2:$L$2071),Data_Tickets!$L$2:$L$2071))} -> 14.04 | D18: =SUMIFS(Data_Tickets!$I$2:$I$2071,Data_Tickets!$C$2:$C$2071,A18) -> -509.89 | E18: =SUMIFS(Team_Month!C:C,Team_Month!A:A,A18) -> 19218.2 | F18: =SUMIFS(Team_Month!D:D,Team_Month!A:A,A18) -> 19400 | G18: =(E18-F18)/F18 -> -0.009371134 | H18: =SUMIFS(Utilization!E:E,Utilization!A:A,A18)/SUMIFS(Utilization!D:D,Utilization!A:A,A18) -> 0.8042328
A19: FUL-DXB | B19: =COUNTIFS(Data_Tickets!$C$2:$C$2071,A19) -> 589 | C19: {=MEDIAN(IF((Data_Tickets!$C$2:$C$2071=A19)*ISNUMBER(Data_Tickets!$L$2:$L$2071),Data_Tickets!$L$2:$L$2071))} -> 24.93 | D19: =SUMIFS(Data_Tickets!$I$2:$I$2071,Data_Tickets!$C$2:$C$2071,A19) -> -393.92 | E19: =SUMIFS(Team_Month!C:C,Team_Month!A:A,A19) -> 100520.2 | F19: =SUMIFS(Team_Month!D:D,Team_Month!A:A,A19) -> 94100 | G19: =(E19-F19)/F19 -> 0.068227418 | H19: =SUMIFS(Utilization!E:E,Utilization!A:A,A19)/SUMIFS(Utilization!D:D,Utilization!A:A,A19) -> 0.78826531
A20: FUL-RUH | B20: =COUNTIFS(Data_Tickets!$C$2:$C$2071,A20) -> 190 | C20: {=MEDIAN(IF((Data_Tickets!$C$2:$C$2071=A20)*ISNUMBER(Data_Tickets!$L$2:$L$2071),Data_Tickets!$L$2:$L$2071))} -> 32.73 | D20: =SUMIFS(Data_Tickets!$I$2:$I$2071,Data_Tickets!$C$2:$C$2071,A20) -> 432.38 | E20: =SUMIFS(Team_Month!C:C,Team_Month!A:A,A20) -> 30022.5 | F20: =SUMIFS(Team_Month!D:D,Team_Month!A:A,A20) -> 31600 | G20: =(E20-F20)/F20 -> -0.049920886 | H20: =SUMIFS(Utilization!E:E,Utilization!A:A,A20)/SUMIFS(Utilization!D:D,Utilization!A:A,A20) -> 0.8478836

Sheet Data_Tickets
A1: ticket_ref | B1: txn_id | C1: team_code | D1: status | E1: opened_at | F1: resolved_at | G1: expected_aed | H1: actual_aed | I1: variance_aed | J1: variance_pct | K1: net_margin_aed | L1: resolution_hours_working | M1: month | N1: opened_date | O1: resolved_date
A2: T-100031 | B2: TXN1288757 | C2: FUL-DXB | D2: RESOLVED | E2: 45719.3 | F2: 45719.678 | G2: 341.61 | H2: 351.27 | I2: =H2-G2 -> 9.66 | J2: =IF(G2=0,"",I2/G2) -> 0.028277861 | K2: 96.8 | L2: 9.08 | M2: 2025-03 | N2: =INT(E2) -> 45719 | O2: =IF(F2="","",INT(F2)) -> 45719
A3: T-100024 | B3: TXN6225066 | C3: CS-AUH | D3: RESOLVED | E3: 45719.329 | F3: 45719.914 | G3: 606.01 | H3: 597.7 | I3: =H3-G3 -> -8.31 | J3: =IF(G3=0,"",I3/G3) -> -0.013712645 | K3: 79.6 | L3: 14.04 | M3: 2025-03 | N3: =INT(E3) -> 45719 | O3: =IF(F3="","",INT(F3)) -> 45719
A4: T-100020 | B4: TXN2070285 | C4: CS-DXB | D4: IN_PROGRESS | E4: 45719.339 | G4: 558.87 | H4: 559.3 | I4: =H4-G4 -> 0.43 | J4: =IF(G4=0,"",I4/G4) -> 0.0007694097 | K4: 153.8 | M4: 2025-03 | N4: =INT(E4) -> 45719 | O4: =IF(F4="","",INT(F4))
A5: T-100038 | B5: TXN6638557 | C5: FUL-DXB | D5: RESOLVED | E5: 45719.353 | F5: 45719.949 | G5: 680.19 | H5: 684.68 | I5: =H5-G5 -> 4.49 | J5: =IF(G5=0,"",I5/G5) -> 0.0066010968 | K5: 267.8 | L5: 14.3 | M5: 2025-03 | N5: =INT(E5) -> 45719 | O5: =IF(F5="","",INT(F5)) -> 45719
A6: T-100032 | B6: TXN1614732 | C6: FUL-DXB | D6: RESOLVED | E6: 45719.374 | F6: 45721.397 | G6: 187.91 | H6: 183.66 | I6: =H6-G6 -> -4.25 | J6: =IF(G6=0,"",I6/G6) -> -0.02261721 | K6: 78.1 | L6: 48.57 | M6: 2025-03 | N6: =INT(E6) -> 45719 | O6: =IF(F6="","",INT(F6)) -> 45721
A7: T-100012 | B7: TXN8864683 | C7: PAY-OPS | D7: RESOLVED | E7: 45719.376 | F7: 45719.96 | G7: 88.42 | H7: 90.15 | I7: =H7-G7 -> 1.73 | J7: =IF(G7=0,"",I7/G7) -> 0.019565709 | K7: 13.3 | L7: 14.03 | M7: 2025-03 | N7: =INT(E7) -> 45719 | O7: =IF(F7="","",INT(F7)) -> 45719
A8: T-100030 | B8: TXN5569520 | C8: FUL-DXB | D8: RESOLVED | E8: 45719.381 | F8: 45722.209 | G8: 201.58 | H8: 204.67 | I8: =H8-G8 -> 3.09 | J8: =IF(G8=0,"",I8/G8) -> 0.015328902 | K8: 49.3 | L8: 67.88 | M8: 2025-03 | N8: =INT(E8) -> 45719 | O8: =IF(F8="","",INT(F8)) -> 45722
A9: T-100007 | B9: TXN5833328 | C9: FIN-OPS | D9: RESOLVED | E9: 45719.392 | F9: 45719.922 | G9: 758.05 | H9: 747.94 | I9: =H9-G9 -> -10.11 | J9: =IF(G9=0,"",I9/G9) -> -0.013336851 | K9: 74.9 | L9: 12.72 | M9: 2025-03 | N9: =INT(E9) -> 45719 | O9: =IF(F9="","",INT(F9)) -> 45719
A10: T-100018 | B10: TXN7168825 | C10: CS-DXB | D10: IN_PROGRESS | E10: 45719.396 | G10: 130.83 | H10: 130.14 | I10: =H10-G10 -> -0.69 | J10: =IF(G10=0,"",I10/G10) -> -0.0052740197 | K10: 31.7 | M10: 2025-03 | N10: =INT(E10) -> 45719 | O10: =IF(F10="","",INT(F10))
A11: T-100004 | B11: TXN6593296 | C11: FIN-OPS | D11: RESOLVED | E11: 45719.425 | F11: 45720.17 | G11: 710.39 | H11: 709.22 | I11: =H11-G11 -> -1.17 | J11: =IF(G11=0,"",I11/G11) -> -0.0016469826 | K11: 68.9 | L11: 17.88 | M11: 2025-03 | N11: =INT(E11) -> 45719 | O11: =IF(F11="","",INT(F11)) -> 45720
A12: T-100011 | B12: TXN3200035 | C12: PAY-OPS | D12: RESOLVED | E12: 45719.429 | F12: 45721.802 | G12: 232.62 | H12: 234.65 | I12: =H12-G12 -> 2.03 | J12: =IF(G12=0,"",I12/G12) -> 0.0087266787 | K12: 41.8 | L12: 56.95 | M12: 2025-03 | N12: =INT(E12) -> 45719 | O12: =IF(F12="","",INT(F12)) -> 45721
A13: T-100008 | B13: TXN5105167 | C13: PAY-OPS | D13: IN_PROGRESS | E13: 45719.438 | G13: 320.13 | H13: 318.92 | I13: =H13-G13 -> -1.21 | J13: =IF(G13=0,"",I13/G13) -> -0.0037797145 | K13: 42.5 | M13: 2025-03 | N13: =INT(E13) -> 45719 | O13: =IF(F13="","",INT(F13))
A14: T-100036 | B14: TXN7239047 | C14: FUL-DXB | D14: RESOLVED | E14: 45719.45 | F14: 45719.959 | G14: 746.38 | H14: 743.04 | I14: =H14-G14 -> -3.34 | J14: =IF(G14=0,"",I14/G14) -> -0.0044749323 | K14: 258.2 | L14: 12.22 | M14: 2025-03 | N14: =INT(E14) -> 45719 | O14: =IF(F14="","",INT(F14)) -> 45719
A15: T-100035 | B15: TXN3548872 | C15: FUL-DXB | D15: RESOLVED | E15: 45719.453 | F15: 45720.658 | G15: 405.97 | H15: 385.07 | I15: =H15-G15 -> -20.9 | J15: =IF(G15=0,"",I15/G15) -> -0.051481637 | K15: 159.8 | L15: 28.92 | M15: 2025-03 | N15: =INT(E15) -> 45719 | O15: =IF(F15="","",INT(F15)) -> 45720
A16: T-100003 | B16: TXN7692901 | C16: FIN-OPS | D16: IN_PROGRESS | E16: 45719.467 | G16: 768.29 | H16: 800.57 | I16: =H16-G16 -> 32.28 | J16: =IF(G16=0,"",I16/G16) -> 0.042015385 | K16: 91.9 | M16: 2025-03 | N16: =INT(E16) -> 45719 | O16: =IF(F16="","",INT(F16))
A17: T-100009 | B17: TXN8627644 | C17: PAY-OPS | D17: RESOLVED | E17: 45719.485 | F17: 45720.206 | G17: 376.18 | H17: 366.63 | I17: =H17-G17 -> -9.55 | J17: =IF(G17=0,"",I17/G17) -> -0.025386783 | K17: 63.9 | L17: 17.32 | M17: 2025-03 | N17: =INT(E17) -> 45719 | O17: =IF(F17="","",INT(F17)) -> 45720
A18: T-100016 | B18: TXN3884202 | C18: CS-DXB | D18: RESOLVED | E18: 45719.486 | F18: 45720.184 | G18: 269.3 | H18: 269.76 | I18: =H18-G18 -> 0.46 | J18: =IF(G18=0,"",I18/G18) -> 0.0017081322 | K18: 47.3 | L18: 16.76 | M18: 2025-03 | N18: =INT(E18) -> 45719 | O18: =IF(F18="","",INT(F18)) -> 45720
A19: T-100042 | B19: TXN1091317 | C19: FUL-RUH | D19: RESOLVED | E19: 45719.508 | F19: 45721.747 | G19: 336.46 | H19: 339.38 | I19: =H19-G19 -> 2.92 | J19: =IF(G19=0,"",I19/G19) -> 0.0086785948 | K19: 121.6 | L19: 53.72 | M19: 2025-03 | N19: =INT(E19) -> 45719 | O19: =IF(F19="","",INT(F19)) -> 45721
A20: T-100021 | B20: TXN2548954 | C20: CS-AUH | D20: RESOLVED | E20: 45719.509 | F20: 45720.044 | G20: 257.96 | H20: 200.82 | I20: =H20-G20 -> -57.14 | J20: =IF(G20=0,"",I20/G20) -> -0.22150721 | K20: 35.9 | L20: 12.83 | M20: 2025-03 | N20: =INT(E20) -> 45719 | O20: =IF(F20="","",INT(F20)) -> 45720
A21: T-100039 | B21: TXN2054714 | C21: FUL-RUH | D21: RESOLVED | E21: 45719.51 | F21: 45721.607 | G21: 235.87 | H21: 231.91 | I21: =H21-G21 -> -3.96 | J21: =IF(G21=0,"",I21/G21) -> -0.016788909 | K21: 43.1 | L21: 50.31 | M21: 2025-03 | N21: =INT(E21) -> 45719 | O21: =IF(F21="","",INT(F21)) -> 45721
A22: T-100015 | B22: TXN9642206 | C22: CS-DXB | D22: RESOLVED | E22: 45719.517 | F22: 45720.352 | G22: 783.79 | H22: 876.92 | I22: =H22-G22 -> 93.13 | J22: =IF(G22=0,"",I22/G22) -> 0.11882009 | K22: 145.5 | L22: 20.03 | M22: 2025-03 | N22: =INT(E22) -> 45719 | O22: =IF(F22="","",INT(F22)) -> 45720
A23: T-100013 | B23: TXN2267384 | C23: PAY-OPS | D23: IN_PROGRESS | E23: 45719.524 | G23: 573.29 | H23: 560.84 | I23: =H23-G23 -> -12.45 | J23: =IF(G23=0,"",I23/G23) -> -0.021716758 | K23: 92.8 | M23: 2025-03 | N23: =INT(E23) -> 45719 | O23: =IF(F23="","",INT(F23))
A24: T-100023 | B24: TXN2143696 | C24: CS-AUH | D24: RESOLVED | E24: 45719.538 | F24: 45719.799 | G24: 1166.62 | H24: 1209.21 | I24: =H24-G24 -> 42.59 | J24: =IF(G24=0,"",I24/G24) -> 0.036507175 | K24: 164.5 | L24: 6.25 | M24: 2025-03 | N24: =INT(E24) -> 45719 | O24: =IF(F24="","",INT(F24)) -> 45719
A25: T-100006 | B25: TXN8316463 | C25: FIN-OPS | D25: RESOLVED | E25: 45719.553 | F25: 45721.38 | G25: 999.01 | H25: 1023.71 | I25: =H25-G25 -> 24.7 | J25: =IF(G25=0,"",I25/G25) -> 0.024724477 | K25: 123.2 | L25: 43.85 | M25: 2025-03 | N25: =INT(E25) -> 45719 | O25: =IF(F25="","",INT(F25)) -> 45721
A26: T-100033 | B26: TXN3267480 | C26: FUL-DXB | D26: RESOLVED | E26: 45719.594 | F26: 45721.342 | G26: 139.78 | H26: 141.71 | I26: =H26-G26 -> 1.93 | J26: =IF(G26=0,"",I26/G26) -> 0.013807412 | K26: 28.7 | L26: 41.93 | M26: 2025-03 | N26: =INT(E26) -> 45719 | O26: =IF(F26="","",INT(F26)) -> 45721
A27: T-100022 | B27: TXN9242703 | C27: CS-AUH | D27: RESOLVED | E27: 45719.597 | F27: 45720.773 | G27: 1325.41 | H27: 1342.72 | I27: =H27-G27 -> 17.31 | J27: =IF(G27=0,"",I27/G27) -> 0.01306011 | K27: 201.8 | L27: 28.25 | M27: 2025-03 | N27: =INT(E27) -> 45719 | O27: =IF(F27="","",INT(F27)) -> 45720
A28: T-100005 | B28: TXN7783870 | C28: FIN-OPS | D28: RESOLVED | E28: 45719.606 | F28: 45720.014 | G28: 685.67 | H28: 673.65 | I28: =H28-G28 -> -12.02 | J28: =IF(G28=0,"",I28/G28) -> -0.017530299 | K28: 118.6 | L28: 9.8 | M28: 2025-03 | N28: =INT(E28) -> 45719 | O28: =IF(F28="","",INT(F28)) -> 45720
A29: T-100034 | B29: TXN2863448 | C29: FUL-DXB | D29: RESOLVED | E29: 45719.651 | F29: 45722.09 | G29: 233.61 | H29: 230.94 | I29: =H29-G29 -> -2.67 | J29: =IF(G29=0,"",I29/G29) -> -0.011429305 | K29: 97.8 | L29: 58.52 | M29: 2025-03 | N29: =INT(E29) -> 45719 | O29: =IF(F29="","",INT(F29)) -> 45722
A30: T-100027 | B30: TXN8406259 | C30: FUL-DXB | D30: RESOLVED | E30: 45719.653 | F30: 45721.064 | G30: 128.19 | H30: 131.08 | I30: =H30-G30 -> 2.89 | J30: =IF(G30=0,"",I30/G30) -> 0.02254466 | K30: 40.8 | L30: 33.87 | M30: 2025-03 | N30: =INT(E30) -> 45719 | O30: =IF(F30="","",INT(F30)) -> 45721
A31: T-100037 | B31: TXN4529331 | C31: FUL-DXB | D31: RESOLVED | E31: 45719.657 | F31: 45721.22 | G31: 193.5 | H31: 204.06 | I31: =H31-G31 -> 10.56 | J31: =IF(G31=0,"",I31/G31) -> 0.054573643 | K31: 56.2 | L31: 37.52 | M31: 2025-03 | N31: =INT(E31) -> 45719 | O31: =IF(F31="","",INT(F31)) -> 45721
A32: T-100014 | B32: TXN5186760 | C32: PAY-OPS | D32: RESOLVED | E32: 45719.658 | F32: 45721.359 | G32: 509.47 | H32: 509 | I32: =H32-G32 -> -0.47 | J32: =IF(G32=0,"",I32/G32) -> -0.00092252733 | K32: 49.6 | L32: 40.84 | M32: 2025-03 | N32: =INT(E32) -> 45719 | O32: =IF(F32="","",INT(F32)) -> 45721
A33: T-100017 | B33: TXN2473901 | C33: CS-DXB | D33: RESOLVED | E33: 45719.667 | F33: 45721.245 | G33: 112.68 | H33: 112.9 | I33: =H33-G33 -> 0.22 | J33: =IF(G33=0,"",I33/G33) -> 0.0019524317 | K33: 18 | L33: 37.88 | M33: 2025-03 | N33: =INT(E33) -> 45719 | O33: =IF(F33="","",INT(F33)) -> 45721
A34: T-100028 | B34: TXN1378252 | C34: FUL-DXB | D34: RESOLVED | E34: 45719.672 | F34: 45721.2 | G34: 2161.56 | H34: 2165.08 | I34: =H34-G34 -> 3.52 | J34: =IF(G34=0,"",I34/G34) -> 0.0016284535 | K34: 663.5 | L34: 36.68 | M34: 2025-03 | N34: =INT(E34) -> 45719 | O34: =IF(F34="","",INT(F34)) -> 45721
A35: T-100041 | B35: TXN1380797 | C35: FUL-RUH | D35: RESOLVED | E35: 45719.678 | F35: 45721.793 | G35: 481.96 | H35: 489.03 | I35: =H35-G35 -> 7.07 | J35: =IF(G35=0,"",I35/G35) -> 0.014669267 | K35: 114 | L35: 50.74 | M35: 2025-03 | N35: =INT(E35) -> 45719 | O35: =IF(F35="","",INT(F35)) -> 45721
A36: T-100019 | B36: TXN8064965 | C36: CS-DXB | D36: RESOLVED | E36: 45719.706 | F36: 45720.793 | G36: 134.1 | H36: 132.06 | I36: =H36-G36 -> -2.04 | J36: =IF(G36=0,"",I36/G36) -> -0.015212528 | K36: 18.4 | L36: 26.09 | M36: 2025-03 | N36: =INT(E36) -> 45719 | O36: =IF(F36="","",INT(F36)) -> 45720
A37: T-100010 | B37: TXN2964557 | C37: PAY-OPS | D37: IN_PROGRESS | E37: 45719.71 | G37: 417.3 | H37: 415.09 | I37: =H37-G37 -> -2.21 | J37: =IF(G37=0,"",I37/G37) -> -0.0052959502 | K37: 73.5 | M37: 2025-03 | N37: =INT(E37) -> 45719 | O37: =IF(F37="","",INT(F37))
A38: T-100029 | B38: TXN6283836 | C38: FUL-DXB | D38: RESOLVED | E38: 45719.712 | F38: 45720.543 | G38: 480.13 | H38: 465.96 | I38: =H38-G38 -> -14.17 | J38: =IF(G38=0,"",I38/G38) -> -0.02951284 | K38: 140.5 | L38: 19.95 | M38: 2025-03 | N38: =INT(E38) -> 45719 | O38: =IF(F38="","",INT(F38)) -> 45720
A39: T-100001 | B39: TXN7612905 | C39: FIN-OPS | D39: RESOLVED | E39: 45719.718 | F39: 45721.338 | G39: 152.26 | H39: 147.16 | I39: =H39-G39 -> -5.1 | J39: =IF(G39=0,"",I39/G39) -> -0.033495337 | K39: 23.4 | L39: 38.87 | M39: 2025-03 | N39: =INT(E39) -> 45719 | O39: =IF(F39="","",INT(F39)) -> 45721
A40: T-100040 | B40: TXN2508763 | C40: FUL-RUH | D40: RESOLVED | E40: 45719.783 | F40: 45721.785 | G40: 855.85 | H40: 826.59 | I40: =H40-G40 -> -29.26 | J40: =IF(G40=0,"",I40/G40) -> -0.034188234 | K40: 246.4 | L40: 48.03 | M40: 2025-03 | N40: =INT(E40) -> 45719 | O40: =IF(F40="","",INT(F40)) -> 45721
...

Sheet Team_Month
A1: team_code | B1: year_month | C1: actual_margin_aed | D1: budget_margin_aed | E1: margin_variance_aed | F1: margin_variance_pct
A2: FIN-OPS | B2: 2025-03 | C2: =SUMIFS(Data_Tickets!$K$2:$K$2071,Data_Tickets!$C$2:$C$2071,A2,Data_Tickets!$M$2:$M$2071,B2) -> 6742.1 | D2: 7300 | E2: =C2-D2 -> -557.9 | F2: =E2/D2 -> -0.076424658
A3: FIN-OPS | B3: 2025-04 | C3: =SUMIFS(Data_Tickets!$K$2:$K$2071,Data_Tickets!$C$2:$C$2071,A3,Data_Tickets!$M$2:$M$2071,B3) -> 9001.5 | D3: 9800 | E3: =C3-D3 -> -798.5 | F3: =E3/D3 -> -0.081479592
A4: FIN-OPS | B4: 2025-05 | C4: =SUMIFS(Data_Tickets!$K$2:$K$2071,Data_Tickets!$C$2:$C$2071,A4,Data_Tickets!$M$2:$M$2071,B4) -> 6108.4 | D4: 5800 | E4: =C4-D4 -> 308.4 | F4: =E4/D4 -> 0.053172414
A5: PAY-OPS | B5: 2025-03 | C5: =SUMIFS(Data_Tickets!$K$2:$K$2071,Data_Tickets!$C$2:$C$2071,A5,Data_Tickets!$M$2:$M$2071,B5) -> 7328.4 | D5: 7000 | E5: =C5-D5 -> 328.4 | F5: =E5/D5 -> 0.046914286
A6: PAY-OPS | B6: 2025-04 | C6: =SUMIFS(Data_Tickets!$K$2:$K$2071,Data_Tickets!$C$2:$C$2071,A6,Data_Tickets!$M$2:$M$2071,B6) -> 9987.4 | D6: 10100 | E6: =C6-D6 -> -112.6 | F6: =E6/D6 -> -0.011148515
A7: PAY-OPS | B7: 2025-05 | C7: =SUMIFS(Data_Tickets!$K$2:$K$2071,Data_Tickets!$C$2:$C$2071,A7,Data_Tickets!$M$2:$M$2071,B7) -> 12982.7 | D7: 13800 | E7: =C7-D7 -> -817.3 | F7: =E7/D7 -> -0.059224638
A8: CS-DXB | B8: 2025-03 | C8: =SUMIFS(Data_Tickets!$K$2:$K$2071,Data_Tickets!$C$2:$C$2071,A8,Data_Tickets!$M$2:$M$2071,B8) -> 16364.5 | D8: 17300 | E8: =C8-D8 -> -935.5 | F8: =E8/D8 -> -0.054075145
A9: CS-DXB | B9: 2025-04 | C9: =SUMIFS(Data_Tickets!$K$2:$K$2071,Data_Tickets!$C$2:$C$2071,A9,Data_Tickets!$M$2:$M$2071,B9) -> 15829.1 | D9: 17500 | E9: =C9-D9 -> -1670.9 | F9: =E9/D9 -> -0.09548
A10: CS-DXB | B10: 2025-05 | C10: =SUMIFS(Data_Tickets!$K$2:$K$2071,Data_Tickets!$C$2:$C$2071,A10,Data_Tickets!$M$2:$M$2071,B10) -> 16846.5 | D10: 15400 | E10: =C10-D10 -> 1446.5 | F10: =E10/D10 -> 0.093928571
A11: CS-AUH | B11: 2025-03 | C11: =SUMIFS(Data_Tickets!$K$2:$K$2071,Data_Tickets!$C$2:$C$2071,A11,Data_Tickets!$M$2:$M$2071,B11) -> 6008.1 | D11: 6100 | E11: =C11-D11 -> -91.9 | F11: =E11/D11 -> -0.015065574
A12: CS-AUH | B12: 2025-04 | C12: =SUMIFS(Data_Tickets!$K$2:$K$2071,Data_Tickets!$C$2:$C$2071,A12,Data_Tickets!$M$2:$M$2071,B12) -> 7343.7 | D12: 7200 | E12: =C12-D12 -> 143.7 | F12: =E12/D12 -> 0.019958333
A13: CS-AUH | B13: 2025-05 | C13: =SUMIFS(Data_Tickets!$K$2:$K$2071,Data_Tickets!$C$2:$C$2071,A13,Data_Tickets!$M$2:$M$2071,B13) -> 5866.4 | D13: 6100 | E13: =C13-D13 -> -233.6 | F13: =E13/D13 -> -0.038295082
... A19: FUL-RUH | B19: 2025-05 | C19: =SUMIFS(Data_Tickets!$K$2:$K$2071,Data_Tickets!$C$2:$C$2071,A19,Data_Tickets!$M$2:$M$2071,B19) -> 11656.9 | D19: 11800 | E19: =C19-D19 -> -143.1 | F19: =E19/D19 -> -0.012127119

Sheet Utilization
A1: team_code | B1: year_month | C1: fte | D1: available_hours | E1: booked_hours | F1: utilization_pct
A2: FIN-OPS | B2: 2025-03 | C2: 6 | D2: 960 | E2: 926 | F2: =E2/D2 -> 0.96458333
A3: FIN-OPS | B3: 2025-04 | C3: 6 | D3: 1008 | E3: 794 | F3: =E3/D3 -> 0.78769841
A4: FIN-OPS | B4: 2025-05 | C4: 6 | D4: 1056 | E4: 850 | F4: =E4/D4 -> 0.80492424
A5: PAY-OPS | B5: 2025-03 | C5: 8 | D5: 1280 | E5: 1065 | F5: =E5/D5 -> 0.83203125
A6: PAY-OPS | B6: 2025-04 | C6: 8 | D6: 1344 | E6: 936 | F6: =E6/D6 -> 0.69642857
A7: PAY-OPS | B7: 2025-05 | C7: 8 | D7: 1408 | E7: 967 | F7: =E7/D7 -> 0.68678977
A8: CS-DXB | B8: 2025-03 | C8: 10 | D8: 1600 | E8: 1231 | F8: =E8/D8 -> 0.769375
A9: CS-DXB | B9: 2025-04 | C9: 10 | D9: 1680 | E9: 1429 | F9: =E9/D9 -> 0.85059524
A10: CS-DXB | B10: 2025-05 | C10: 10 | D10: 1760 | E10: 1494 | F10: =E10/D10 -> 0.84886364
A11: CS-AUH | B11: 2025-03 | C11: 6 | D11: 960 | E11: 702 | F11: =E11/D11 -> 0.73125
A12: CS-AUH | B12: 2025-04 | C12: 6 | D12: 1008 | E12: 776 | F12: =E12/D12 -> 0.76984127
A13: CS-AUH | B13: 2025-05 | C13: 6 | D13: 1056 | E13: 954 | F13: =E13/D13 -> 0.90340909
... A19: FUL-RUH | B19: 2025-05 | C19: 9 | D19: 1584 | E19: 1350 | F19: =E19/D19 -> 0.85227273

Sheet Weekly
A1: week_start (Mon) | B1: opened | C1: resolved | D1: resolution_rate
A2: 45719 | B2: =COUNTIFS(Data_Tickets!$N$2:$N$2071,">="&A2,Data_Tickets!$N$2:$N$2071,"<"&A2+7) -> 173 | C2: =COUNTIFS(Data_Tickets!$O$2:$O$2071,">="&A2,Data_Tickets!$O$2:$O$2071,"<"&A2+7) -> 156 | D2: =IF(B2=0,"",C2/B2) -> 0.9017341
A3: 45726 | B3: =COUNTIFS(Data_Tickets!$N$2:$N$2071,">="&A3,Data_Tickets!$N$2:$N$2071,"<"&A3+7) -> 158 | C3: =COUNTIFS(Data_Tickets!$O$2:$O$2071,">="&A3,Data_Tickets!$O$2:$O$2071,"<"&A3+7) -> 146 | D3: =IF(B3=0,"",C3/B3) -> 0.92405063
A4: 45733 | B4: =COUNTIFS(Data_Tickets!$N$2:$N$2071,">="&A4,Data_Tickets!$N$2:$N$2071,"<"&A4+7) -> 152 | C4: =COUNTIFS(Data_Tickets!$O$2:$O$2071,">="&A4,Data_Tickets!$O$2:$O$2071,"<"&A4+7) -> 143 | D4: =IF(B4=0,"",C4/B4) -> 0.94078947
A5: 45740 | B5: =COUNTIFS(Data_Tickets!$N$2:$N$2071,">="&A5,Data_Tickets!$N$2:$N$2071,"<"&A5+7) -> 128 | C5: =COUNTIFS(Data_Tickets!$O$2:$O$2071,">="&A5,Data_Tickets!$O$2:$O$2071,"<"&A5+7) -> 125 | D5: =IF(B5=0,"",C5/B5) -> 0.9765625
A6: 45747 | B6: =COUNTIFS(Data_Tickets!$N$2:$N$2071,">="&A6,Data_Tickets!$N$2:$N$2071,"<"&A6+7) -> 182 | C6: =COUNTIFS(Data_Tickets!$O$2:$O$2071,">="&A6,Data_Tickets!$O$2:$O$2071,"<"&A6+7) -> 167 | D6: =IF(B6=0,"",C6/B6) -> 0.91758242
A7: 45754 | B7: =COUNTIFS(Data_Tickets!$N$2:$N$2071,">="&A7,Data_Tickets!$N$2:$N$2071,"<"&A7+7) -> 164 | C7: =COUNTIFS(Data_Tickets!$O$2:$O$2071,">="&A7,Data_Tickets!$O$2:$O$2071,"<"&A7+7) -> 157 | D7: =IF(B7=0,"",C7/B7) -> 0.95731707
A8: 45761 | B8: =COUNTIFS(Data_Tickets!$N$2:$N$2071,">="&A8,Data_Tickets!$N$2:$N$2071,"<"&A8+7) -> 148 | C8: =COUNTIFS(Data_Tickets!$O$2:$O$2071,">="&A8,Data_Tickets!$O$2:$O$2071,"<"&A8+7) -> 138 | D8: =IF(B8=0,"",C8/B8) -> 0.93243243
A9: 45768 | B9: =COUNTIFS(Data_Tickets!$N$2:$N$2071,">="&A9,Data_Tickets!$N$2:$N$2071,"<"&A9+7) -> 151 | C9: =COUNTIFS(Data_Tickets!$O$2:$O$2071,">="&A9,Data_Tickets!$O$2:$O$2071,"<"&A9+7) -> 147 | D9: =IF(B9=0,"",C9/B9) -> 0.97350993
A10: 45775 | B10: =COUNTIFS(Data_Tickets!$N$2:$N$2071,">="&A10,Data_Tickets!$N$2:$N$2071,"<"&A10+7) -> 176 | C10: =COUNTIFS(Data_Tickets!$O$2:$O$2071,">="&A10,Data_Tickets!$O$2:$O$2071,"<"&A10+7) -> 154 | D10: =IF(B10=0,"",C10/B10) -> 0.875
A11: 45782 | B11: =COUNTIFS(Data_Tickets!$N$2:$N$2071,">="&A11,Data_Tickets!$N$2:$N$2071,"<"&A11+7) -> 168 | C11: =COUNTIFS(Data_Tickets!$O$2:$O$2071,">="&A11,Data_Tickets!$O$2:$O$2071,"<"&A11+7) -> 162 | D11: =IF(B11=0,"",C11/B11) -> 0.96428571
A12: 45789 | B12: =COUNTIFS(Data_Tickets!$N$2:$N$2071,">="&A12,Data_Tickets!$N$2:$N$2071,"<"&A12+7) -> 159 | C12: =COUNTIFS(Data_Tickets!$O$2:$O$2071,">="&A12,Data_Tickets!$O$2:$O$2071,"<"&A12+7) -> 149 | D12: =IF(B12=0,"",C12/B12) -> 0.93710692
A13: 45796 | B13: =COUNTIFS(Data_Tickets!$N$2:$N$2071,">="&A13,Data_Tickets!$N$2:$N$2071,"<"&A13+7) -> 165 | C13: =COUNTIFS(Data_Tickets!$O$2:$O$2071,">="&A13,Data_Tickets!$O$2:$O$2071,"<"&A13+7) -> 145 | D13: =IF(B13=0,"",C13/B13) -> 0.87878788
A14: 45803 | B14: =COUNTIFS(Data_Tickets!$N$2:$N$2071,">="&A14,Data_Tickets!$N$2:$N$2071,"<"&A14+7) -> 146 | C14: =COUNTIFS(Data_Tickets!$O$2:$O$2071,">="&A14,Data_Tickets!$O$2:$O$2071,"<"&A14+7) -> 58 | D14: =IF(B14=0,"",C14/B14) -> 0.39726027
