Workbook

Sheet README
A1: Mizan - simulated portfolio project. Fictional client, synthetic data. Blue header = table; edit data rows only.
A3: Sheet | B3: Purpose
A4: Stakeholder Register | B4: Who is involved, influence/interest, engagement strategy
A5: RACI | B5: Responsibility matrix per deliverable
A6: Requirements Trace | B6: BR/FR/NFR to epic/story/UAT traceability
A7: Backlog | B7: Prioritized sprint backlog with MoSCoW and story points
A8: Sprint Velocity | B8: Planned vs completed points (formulas)
A9: RAID Log | B9: Risks, assumptions, issues, dependencies with scoring formula
A10: Change Log | B10: Change control decisions
A11: UAT | B11: UAT cases and results
A12: Defects | B12: Defect log
A13: Defect Triage Matrix | B13: Severity and response rules
A14: Exception Tracker | B14: December 2024 exceptions from the reconciliation run (synthetic data); status and SLA breach are formulas
A15: KPI Tracker | B15: Match rate, clearance velocity and resolution KPIs computed by formula from the tracker

Sheet Stakeholder Register
A1: ID | B1: Name (fictional) | C1: Role | D1: Project role | E1: Influence | F1: Interest | G1: Strategy | H1: Needs / notes
A2: SH-01 | B2: Maryam Al Hosani | C2: Finance Controller | D2: Sponsor and Product Owner | E2: High | F2: High | G2: Manage closely | H2: Owns scope, priority and go-live decision
A3: SH-02 | B3: Karthik Raman | C3: Finance Manager | D3: Approver, process SME | E3: High | F3: High | G3: Manage closely | H3: Wants approvals tracked and queryable; limits own approval queue to variances above AED 5,000
A4: SH-03 | B4: Sana Qureshi | C4: Finance Analyst | D4: Primary user | E4: Medium | F4: High | G4: Keep informed, involve in UAT | H4: Spends most of the day on VLOOKUP matching; wants fewer false breaks
A5: SH-04 | B5: Priya Menon | C5: Revenue Accountant | D5: User at month-end close | E5: Medium | F5: High | G5: Keep informed | H5: Cut-off errors from UTC vs GST dates; needs clean period totals
A6: SH-05 | B6: Omar Haddad | C6: Head of Payments Partnerships | D6: Gateway contracts, fee disputes | E6: Medium | F6: Medium | G6: Keep satisfied | H6: Needs fee evidence per transaction to dispute with gateways
A7: SH-06 | B7: Daniel Okafor | C7: Engineering Lead | D7: Delivery lead | E7: High | F7: High | G7: Manage closely | H7: Owns build estimates, ERP integration risk
A8: SH-07 | B8: Layla Siddiqui | C8: QA Lead | D8: Test owner | E8: Medium | F8: High | G8: Keep informed | H8: Needs testable rules and seed data
A9: SH-08 | B9: Nadia Farouk | C9: Data Engineer (part-time) | D9: Pipelines, data models | E9: Low | F9: High | G9: Keep informed | H9: Supports ingestion and views
A10: SH-09 | B10: Hassan Raza | C10: Internal Audit | D10: Audit evidence consumer | E10: Medium | F10: Medium | G10: Keep satisfied | H10: Needs immutable trail and period export
A11: SH-10 | B11: Rahul Nair | C11: Scrum Master (part-time) | D11: Ceremony facilitation | E11: Low | F11: Medium | G11: Keep informed | H11: Facilitates sprint cadence
A12: SH-11 | B12: Imran Kathat | C12: Business Analyst | D12: Requirements, process design, UAT coordination | E12: High | F12: High | G12: Author | H12: Single point for requirements traceability

Sheet RACI
A1: R=Responsible, A=Accountable, C=Consulted, I=Informed
A3: Deliverable / activity | B3: Controller (PO) | C3: Finance Mgr | D3: Analyst | E3: Eng Lead | F3: QA Lead | G3: BA | H3: Data Eng | I3: Audit
A4: Elicitation workshops and interviews | B4: C | C4: C | D4: C | E4: C | F4: I | G4: R/A | H4: I | I4: C
A5: BRD authoring | B5: A | C5: C | D5: C | E5: C | F5: I | G5: R | H5: I | I5: C
A6: BRD sign-off | B6: A/R | C6: C | D6: I | E6: C | F6: I | G6: R | H6: I | I6: I
A7: Backlog prioritization (MoSCoW) | B7: A | C7: C | D7: C | E7: C | F7: I | G7: R | H7: I | I7: I
A8: Gherkin acceptance criteria | B8: A | C8: C | D8: C | E8: C | F8: C | G8: R | H8: I | I8: I
A9: Matching and tolerance rules definition | B9: A | C9: R | D9: C | E9: C | F9: I | G9: R | H9: C | I9: I
A10: Fee schedule data supply | B10: I | C10: A | D10: I | E10: I | F10: I | G10: C | H10: I | I10: I
A11: Build ingestion and matching | B11: I | C11: I | D11: I | E11: A/R | F11: C | G11: C | H11: R | I11: I
A12: ERP integration | B12: I | C12: C | D12: I | E12: A/R | F12: C | G12: C | H12: C | I12: I
A13: Test planning and fixtures | B13: I | C13: I | D13: C | E13: C | F13: A/R | G13: R | H13: C | I13: I
A14: UAT execution | B14: A | C14: R | D14: R | E14: I | F14: C | G14: R | H14: I | I14: I
... A19: Go-live decision | B19: A/R | C19: C | D19: C | E19: C | F19: C | G19: R | H19: I | I19: I

Sheet Requirements Trace
A1: Req ID | B1: Type | C1: Requirement | D1: Priority | E1: Source stakeholder | F1: Epic / Story | G1: UAT cases
A2: BR-01 | B2: Business | C2: Eliminate manual portal exports, spreadsheet matching and email approvals from daily reconciliation | D2: Must | E2: Finance Controller | F2: MIZ-E1, MIZ-E4
A3: BR-02 | B3: Business | C3: Reconcile every gateway settlement to a ledger invoice with net variance explained to AED 0.50 | D3: Must | E3: Finance Controller | F3: MIZ-E2
A4: BR-03 | B4: Business | C4: Every unmatched item has an owner, a flag and a due time | D4: Must | E4: Finance Manager | F4: MIZ-E3
A5: BR-04 | B5: Business | C5: Management can see match rate, clearance velocity and daily resolution rate without asking for spreadsheets | D5: Should | E5: Finance Controller | F5: MIZ-E5
A6: BR-05 | B6: Business | C6: Every adjustment is approved, posted and traceable for audit | D6: Must | E6: Internal Audit | F6: MIZ-E4, MIZ-E5
A7: FR-01 | B7: Functional | C7: Ingest gateway settlement batches via signed webhook with idempotency | D7: Must | E7: Finance Analyst | F7: MIZ-101 | G7: UAT-01, UAT-02
A8: FR-02 | B8: Functional | C8: Detect and backfill missing batches by scheduled polling | D8: Should | E8: Finance Ops Lead | F8: MIZ-102 | G8: UAT-03
A9: FR-03 | B9: Functional | C9: Match settlements to the latest non-void ledger invoice by gateway and transaction reference | D9: Must | E9: Finance Analyst | F9: MIZ-103 | G9: UAT-04
A10: FR-04 | B10: Functional | C10: Price each settlement against the fee schedule effective on its settlement date, including 5% VAT on the fee | D10: Must | E10: Head of Payments | F10: MIZ-104 | G10: UAT-05
A11: FR-05 | B11: Functional | C11: Report dates in GST and tag differences that are explained only by the UTC/GST boundary | D11: Must | E11: Revenue Accountant | F11: MIZ-105 | G11: UAT-06
A12: FR-06 | B12: Functional | C12: Flag orphaned gateway and ledger records after a 3-working-day grace period | D12: Must | E12: Finance Analyst | F12: MIZ-106 | G12: UAT-07
A13: FR-07 | B13: Functional | C13: Route exceptions to owner queues by flag | D13: Should | E13: Finance Ops Lead | F13: MIZ-107 | G13: UAT-08
A14: FR-08 | B14: Functional | C14: Require manager approval above AED 5,000 with a 4-working-hour SLA and escalation | D14: Must | E14: Finance Manager | F14: MIZ-108 | G14: UAT-09, UAT-10, UAT-10R
A15: FR-09 | B15: Functional | C15: Post approved journals to the ERP once, linked to the exception | D15: Must | E15: Finance Analyst | F15: MIZ-109 | G15: UAT-11, UAT-12
A16: FR-10 | B16: Functional | C16: Provide KPI dashboard and exception tracker | D16: Should | E16: Finance Controller | F16: MIZ-110 | G16: UAT-13
A17: FR-11 | B17: Functional | C17: Export period audit report with approver, timestamps and journal reference | D17: Should | E17: Internal Audit | F17: MIZ-111 | G17: UAT-14
A18: NFR-01 | B18: Non-functional | C18: Process a 26,000-row monthly volume reconciliation in under 5 minutes | D18: Must | E18: Eng Lead | F18: MIZ-103 | G18: UAT-04
... A22: NFR-05 | B22: Non-functional | C22: Keep financial records for 5 years (VAT) in a UAE-hosted region | D22: Must | E22: Internal Audit | F22: MIZ-111 | G22: UAT-14

Sheet Backlog
A1: Rank | B1: Key | C1: Epic | D1: Story | E1: Persona | F1: MoSCoW | G1: Priority | H1: Story points | I1: Sprint | J1: Status
A2: 1 | B2: MIZ-101 | C2: MIZ-E1 | D2: Webhook receiver with signature verification and idempotency | E2: Finance Analyst | F2: Must | G2: High | H2: 5 | I2: MIZ Sprint 1 | J2: Done
A3: 2 | B3: MIZ-102 | C3: MIZ-E1 | D3: Scheduled polling fallback for missed batches | E3: Finance Ops Lead | F3: Should | G3: Medium | H3: 5 | I3: MIZ Sprint 1 | J3: Done
A4: 3 | B4: MIZ-103 | C4: MIZ-E2 | D4: Match gateway settlements to ledger invoices within tolerance | E4: Finance Analyst | F4: Must | G4: Highest | H4: 8 | I4: MIZ Sprint 2 | J4: Done
A5: 4 | B5: MIZ-104 | C5: MIZ-E2 | D5: Price settlements against fee schedule including VAT on fee | E5: Head of Payments Partnerships | F5: Must | G5: Highest | H5: 8 | I5: MIZ Sprint 2 | J5: Done
A6: 5 | B6: MIZ-105 | C6: MIZ-E2 | D6: Classify UTC vs GST timing differences | E6: Revenue Accountant | F6: Must | G6: High | H6: 5 | I6: MIZ Sprint 3 | J6: Done
A7: 6 | B7: MIZ-106 | C7: MIZ-E3 | D7: Detect orphaned records in both directions | E7: Finance Analyst | F7: Must | G7: High | H7: 5 | I7: MIZ Sprint 3 | J7: Done
A8: 7 | B8: MIZ-107 | C8: MIZ-E3 | D8: Route exceptions to owners by decision table | E8: Finance Ops Lead | F8: Should | G8: Medium | H8: 5 | I8: MIZ Sprint 3 | J8: Done
A9: 8 | B9: MIZ-108 | C9: MIZ-E4 | D9: In-tool approval with thresholds and SLA escalation | E9: Finance Manager | F9: Must | G9: High | H9: 8 | I9: MIZ Sprint 4 | J9: Done
A10: 9 | B10: MIZ-109 | C10: MIZ-E4 | D10: Post journal adjustments to the ERP via API with idempotency | E10: Finance Analyst | F10: Must | G10: High | H10: 8 | I10: MIZ Sprint 4 | J10: Done
A11: 10 | B11: MIZ-110 | C11: MIZ-E5 | D11: Reconciliation KPI dashboard and exception tracker | E11: Finance Controller | F11: Should | G11: Medium | H11: 5 | I11: MIZ Sprint 5 | J11: Done
A12: 11 | B12: MIZ-111 | C12: MIZ-E5 | D12: Export reconciliation audit report for internal audit | E12: Internal Auditor | F12: Should | G12: Medium | H12: 8 | I12: MIZ Sprint 5 | J12: Done

Sheet Sprint Velocity
A1: Average velocity excludes Sprint 0 (discovery).
A3: Sprint | B3: Start | C3: End | D3: Committed SP | E3: Completed SP | F3: Completion % | G3: Focus
A4: Sprint 0 - Discovery | B4: 2024-10-07 | C4: 2024-10-18 | D4: 0 | E4: 0 | F4: =IF(D4=0,"n/a",E4/D4) -> n/a | G4: Elicitation, baseline, BRD v0.1
A5: MIZ Sprint 1 | B5: 2024-10-21 | C5: 2024-11-01 | D5: 10 | E5: 10 | F5: =IF(D5=0,"n/a",E5/D5) -> 1 | G5: Webhook and polling ingestion
A6: MIZ Sprint 2 | B6: 2024-11-04 | C6: 2024-11-15 | D6: 16 | E6: 16 | F6: =IF(D6=0,"n/a",E6/D6) -> 1 | G6: Matching and fee pricing
A7: MIZ Sprint 3 | B7: 2024-11-18 | C7: 2024-11-29 | D7: 15 | E7: 15 | F7: =IF(D7=0,"n/a",E7/D7) -> 1 | G7: Timing, orphans, routing
A8: MIZ Sprint 4 | B8: 2024-12-02 | C8: 2024-12-13 | D8: 16 | E8: 16 | F8: =IF(D8=0,"n/a",E8/D8) -> 1 | G8: Approvals and ERP posting (National Day 2-3 Dec)
A9: MIZ Sprint 5 | B9: 2024-12-16 | C9: 2024-12-27 | D9: 13 | E9: 13 | F9: =IF(D9=0,"n/a",E9/D9) -> 1 | G9: Dashboard, audit export, hardening
A11: Average velocity (Sprints 1-5) | E11: =AVERAGE(E5:E9) -> 14
A12: Total completed SP | E12: =SUM(E4:E9) -> 70

Sheet RAID Log
A1: ID | B1: Type | C1: Description | D1: Impact (1-5) | E1: Probability (1-5) | F1: Score | G1: Owner | H1: Response / mitigation | I1: Status | J1: Raised
A2: R-01 | B2: Risk | C2: Gateway webhook delivery is delayed or dropped during peak settlement windows | D2: 4 | E2: 3 | F2: =D4*E4 -> 12 | G2: Daniel Okafor | H2: Polling fallback every 15 minutes (MIZ-102); batch-gap alert | I2: Mitigated | J2: 2024-10-08
A3: R-02 | B3: Risk | C3: Legacy ledger stamps posting dates in UTC for one entity, creating false month-end breaks | D3: 4 | E3: 4 | F3: =D5*E5 -> 12 | G3: Imran Kathat | H3: Timezone classification rule (MIZ-105); finance to confirm affected entity list | I3: Mitigated | J3: 2024-10-10
A4: R-03 | B4: Risk | C4: ERP sandbox access delayed, blocking posting integration | D4: 4 | E4: 3 | F4: =D6*E6 -> 12 | G4: Daniel Okafor | H4: Mock ERP service with recorded contract; escalate via Controller by 25 Oct | I4: Closed | J4: 2024-10-09
A5: R-04 | B5: Risk | C5: Analyst availability drops at month-end, slowing UAT feedback | D5: 3 | E5: 4 | F5: =D7*E7 -> 10 | G5: Imran Kathat | H5: Schedule UAT outside close window (30 Dec - 10 Jan, avoiding days 1-3 of month) | I5: Closed | J5: 2024-10-15
A6: R-05 | B6: Risk | C6: Scope creep: refunds and chargebacks requested mid-project | D6: 3 | E6: 4 | F6: =D8*E8 -> 20 | G6: Imran Kathat | H6: Change control (CR-001); deferred to release 1.1 | I6: Closed | J6: 2024-11-12
A7: R-06 | B7: Risk | C7: UAE National Day holiday (2-3 Dec) reduces Sprint 4 capacity | D7: 2 | E7: 5 | F7: =D9*E9 -> 15 | G7: Rahul Nair | H7: Sprint 4 commitment reduced; MIZ-110 moved to Sprint 5 | I7: Closed | J7: 2024-11-18
A8: I-01 | B8: Issue | C8: ERP returns HTTP 429 when posting more than ~40 journals per minute | D8: 4 | E8: 5 | F8: =D10*E10 -> 10 | G8: Daniel Okafor | H8: Chunked posting with backoff and resume (MIZ-109 scenario 3) | I8: Closed | J8: 2024-12-04
A9: I-02 | B9: Issue | C9: Re-issued invoices not voided in ERP produce two candidate matches per transaction | D9: 3 | E9: 5 | F9: =D11*E11 -> 15 | G9: Imran Kathat | H9: Latest non-void invoice rule via ROW_NUMBER (MIZ-103) | I9: Closed | J9: 2024-11-06
A10: A-01 | B10: Assumption | C10: Gateways provide HMAC-signed webhooks and a batch-listing API | D10: 5 | E10: 2 | F10: =D12*E12 -> 12 | G10: Omar Haddad | H10: Confirmed in technical call with both gateways, 14 Oct | I10: Validated | J10: 2024-10-08
A11: A-02 | B11: Assumption | C11: Contracted fee schedules are available per rail and effective date | D11: 5 | E11: 3 | F11: =D13*E13 -> 6 | G11: Omar Haddad | H11: Contracts supplied 21 Oct; one rail (AANI) missing, handled in CR-004 | I11: Validated | J11: 2024-10-08
A12: D-01 | B12: Dependency | C12: ERP sandbox credentials and API documentation | D12: 4 | E12: 3 | F12: =D14*E14 -> 0 | G12: Daniel Okafor | H12: Delivered 29 Oct | I12: Closed | J12: 2024-10-09
A13: D-02 | B13: Dependency | C13: Finance to supply 3 months of historical reconciliation spreadsheets for baseline | D13: 3 | E13: 2 | F13: =D15*E15 -> 0 | G13: Sana Qureshi | H13: Delivered 16 Oct | I13: Closed | J13: 2024-10-09

Sheet Change Log
A1: CR ID | B1: Date | C1: Requested by | D1: Change | E1: Impact assessment | F1: Decision | G1: Approvers | H1: Status
A2: CR-001 | B2: 2024-11-12 | C2: Maryam Al Hosani | D2: Add refunds and chargebacks to the matching engine | E2: +13 SP, 2 sprints; delays go-live by 3 weeks | F2: Rejected for 1.0, added to release 1.1 backlog | G2: Controller (decision), BA, Eng Lead | H2: Closed
A3: CR-002 | B3: 2024-12-11 | C3: Priya Menon | D3: Count the orphan grace period in working days (SIT defect DEF-009: weekend false positives) | E3: +1 SP; no date impact | F3: Approved | G3: Controller, QA Lead | H3: Implemented 2024-12-18
A4: CR-003 | B4: 2024-11-20 | C4: Karthik Raman | D4: Reduce match tolerance from AED 1.00 to AED 0.50 | E4: 0 SP; parameter change; re-baseline of test data | F4: Approved | G4: Controller, Finance Mgr | H4: Implemented 2024-11-22
A5: CR-004 | B5: 2024-11-14 | C5: Omar Haddad | D5: Add AANI instant-payment rail to the fee schedule and test data | E5: +2 SP | F5: Approved | G5: Controller, Eng Lead | H5: Implemented 2024-11-29

Sheet UAT
A1: Case | B1: Story | C1: Scenario | D1: Type | E1: Tester | F1: Result | G1: Date
A2: UAT-01 | B2: MIZ-101 | C2: Signed batch ingested and row count matches declared rows | D2: Functional | E2: Sana Qureshi | F2: Pass | G2: 2024-12-31
A3: UAT-02 | B3: MIZ-101 | C3: Invalid signature rejected; no rows written | D3: Security | E3: Layla Siddiqui | F3: Pass | G3: 2024-12-31
A4: UAT-03 | B4: MIZ-102 | C4: Missed batch is back-filled within 15 minutes | D4: Functional | E4: Sana Qureshi | F4: Pass | G4: 2025-01-02
A5: UAT-04 | B5: MIZ-103 | C5: Exact, within-tolerance and beyond-tolerance rows classified correctly | D5: Functional | E5: Sana Qureshi | F5: Pass | G5: 2025-01-02
A6: UAT-05 | B6: MIZ-104 | C6: Gateway overcharge detected with fee variance AED 27.56 on test row | D6: Functional | E6: Omar Haddad | F6: Pass | G6: 2025-01-02
A7: UAT-06 | B7: MIZ-105 | C7: 30 Nov 21:40 UTC settlement tagged as timing mismatch | D7: Functional | E7: Priya Menon | F7: Pass | G7: 2025-01-03
A8: UAT-07 | B8: MIZ-106 | C8: Weekend does not consume the orphan grace period | D8: Regression | E8: Priya Menon | F8: Pass | G8: 2025-01-03
A9: UAT-08 | B9: MIZ-107 | C9: Each flag lands in the correct owner queue | D9: Functional | E9: Sana Qureshi | F9: Pass | G9: 2025-01-06
A10: UAT-09 | B10: MIZ-108 | C10: Variance of AED 5,000.01 blocks posting until manager approval | D10: Functional | E10: Karthik Raman | F10: Pass | G10: 2025-01-06
A11: UAT-10 | B11: MIZ-108 | C11: SLA escalation fires after 4 working hours | D11: Functional | E11: Karthik Raman | F11: Fail | G11: 2025-01-06
A12: UAT-10R | B12: MIZ-108 | C12: Retest SLA escalation after fix DEF-013 | D12: Retest | E12: Karthik Raman | F12: Pass | G12: 2025-01-08
... A16: UAT-14 | B16: MIZ-111 | C16: Audit export for closed December period complete | D16: Functional | E16: Hassan Raza | F16: Pass | G16: 2025-01-09

Sheet Defects
A1: ID | B1: Title | C1: Severity | D1: Priority | E1: Found in | F1: Story | G1: Status | H1: Found | I1: Fixed | J1: Root cause
A2: DEF-001 | B2: Duplicate rows when webhook and poller race | C2: S2 | D2: P2 | E2: SIT | F2: MIZ-102 | G2: Closed | H2: 2024-11-05 | I2: 2024-11-08 | J2: Missing unique constraint on event key
A3: DEF-002 | B3: Tolerance applied to absolute gross instead of net | C3: S1 | D3: P1 | E3: SIT | F3: MIZ-103 | G3: Closed | H3: 2024-11-13 | I3: 2024-11-14 | J3: Wrong column in comparison
A4: DEF-003 | B4: Re-issued invoice produced two matches | C4: S2 | D4: P1 | E4: SIT | F4: MIZ-103 | G4: Closed | H4: 2024-11-06 | I4: 2024-11-11 | J4: Missing latest-invoice window rule
A5: DEF-004 | B5: VAT on fee rounded per row sum, not per row | C5: S3 | D5: P3 | E5: SIT | F5: MIZ-104 | G5: Closed | H5: 2024-11-15 | I5: 2024-11-18 | J5: Rounding applied after aggregation
A6: DEF-005 | B6: Fee schedule not effective-dated; mid-month rate change misprices | C6: S2 | D6: P2 | E6: SIT | F6: MIZ-104 | G6: Closed | H6: 2024-11-20 | I6: 2024-11-25 | J6: Join ignored effective_to
A7: DEF-006 | B7: Month-end settlement shown in wrong period in GST report | C7: S2 | D7: P1 | E7: SIT | F7: MIZ-105 | G7: Closed | H7: 2024-12-02 | I7: 2024-12-05 | J7: UTC date used for period bucket
A8: DEF-007 | B8: Dead-letter alert posted twice | C8: S4 | D8: P4 | E8: SIT | F8: MIZ-101 | G8: Closed | H8: 2024-11-07 | I8: 2024-11-12 | J8: Retry handler re-raised
A9: DEF-008 | B9: Owner empty for UNCLASSIFIED_VARIANCE | C9: S3 | D9: P2 | E9: SIT | F9: MIZ-107 | G9: Closed | H9: 2024-12-03 | I9: 2024-12-04 | J9: Missing default branch in routing table
A10: DEF-009 | B10: Paid Thursday invoice flagged orphan on Sunday | C10: S2 | D10: P1 | E10: SIT | F10: MIZ-106 | G10: Closed | H10: 2024-12-11 | I10: 2024-12-18 | J10: Grace counted calendar days (CR-002)
A11: DEF-010 | B11: Self-approval possible via direct link | C11: S1 | D11: P1 | E11: SIT | F11: MIZ-108 | G11: Closed | H11: 2024-12-12 | I11: 2024-12-13 | J11: Authorisation checked in UI only
A12: DEF-011 | B12: Posting retried after commit created second journal | C12: S1 | D12: P1 | E12: SIT | F12: MIZ-109 | G12: Closed | H12: 2024-12-16 | I12: 2024-12-17 | J12: Idempotency key not sent on retry
... A14: DEF-013 | B14: SLA escalation timer counts weekends | C14: S2 | D14: P2 | E14: UAT | F14: MIZ-108 | G14: Closed | H14: 2025-01-06 | I14: 2025-01-07 | J14: Timer used elapsed clock hours

Sheet Defect Triage Matrix
A1: Severity | B1: Definition | C1: Priority / action | D1: Response SLA | E1: Fix SLA
A2: S1 Critical | B2: Data loss, wrong money posted, security bypass | C2: P1 - fix before next build; stop-ship | D2: Same day | E2: 4 hours
A3: S2 Major | B3: Core rule wrong, workaround exists | C3: P1/P2 - fix in current sprint | D3: 1 working day | E3: 2 working days
A4: S3 Moderate | B4: Incorrect output in edge case, no money impact | C4: P2/P3 - next sprint | D4: 2 working days | E4: Next sprint
A5: S4 Minor | B5: Cosmetic or logging | C5: P4 - backlog | D5: 3 working days | E5: Backlog

Sheet Exception Tracker
A1: Synthetic December 2024 run. Clearance hours exclude Saturday/Sunday. SLA (working hours): timing 1; variance > AED 5,000: 4; fee dispute 120; orphan 48; other 24.
A3: Exception | B3: Txn ref | C3: Flag | D3: Variance AED | E3: Owner | F3: Opened (GST) | G3: Resolved (GST) | H3: Clearance (working h) | I3: Status | J3: SLA target (working h) | K3: SLA check
A4: EXC-8606 | B4: TX2423001 | C4: FEE_VARIANCE_BREACH | D4: -2.03 | E4: payments-partnerships | F4: 45628 | G4: 45632.428 | H4: 96.26 | I4: =IF(G4="","OPEN","RESOLVED") -> RESOLVED | J4: =IF(C4="TIMING_MISMATCH_TIMEZONE",1,IF(ABS(D4)>5000,4,IF(C4="FEE_VARIANCE_BREACH",120,IF(LEFT(C4,8)="ORPHANED",48,24)))) -> 120 | K4: =IF(H4="","",IF(H4>J4,"BREACH","OK")) -> OK
A5: EXC-8258 | B5: TX2410071 | C5: FEE_VARIANCE_BREACH | D5: -0.87 | E5: payments-partnerships | F5: 45628 | G5: 45630.927 | H5: 60.26 | I5: =IF(G5="","OPEN","RESOLVED") -> RESOLVED | J5: =IF(C5="TIMING_MISMATCH_TIMEZONE",1,IF(ABS(D5)>5000,4,IF(C5="FEE_VARIANCE_BREACH",120,IF(LEFT(C5,8)="ORPHANED",48,24)))) -> 120 | K5: =IF(H5="","",IF(H5>J5,"BREACH","OK")) -> OK
A6: EXC-8315 | B6: TX2412182 | C6: ORPHANED_LEDGER_RECORD | D6: -137.11 | E6: revenue-accounting | F6: 45628 | G6: 45631.262 | H6: 68.29 | I6: =IF(G6="","OPEN","RESOLVED") -> RESOLVED | J6: =IF(C6="TIMING_MISMATCH_TIMEZONE",1,IF(ABS(D6)>5000,4,IF(C6="FEE_VARIANCE_BREACH",120,IF(LEFT(C6,8)="ORPHANED",48,24)))) -> 48 | K6: =IF(H6="","",IF(H6>J6,"BREACH","OK")) -> BREACH
A7: EXC-8316 | B7: TX2412206 | C7: FEE_VARIANCE_BREACH | D7: -1.45 | E7: payments-partnerships | F7: 45628 | G7: 45631.223 | H7: 67.34 | I7: =IF(G7="","OPEN","RESOLVED") -> RESOLVED | J7: =IF(C7="TIMING_MISMATCH_TIMEZONE",1,IF(ABS(D7)>5000,4,IF(C7="FEE_VARIANCE_BREACH",120,IF(LEFT(C7,8)="ORPHANED",48,24)))) -> 120 | K7: =IF(H7="","",IF(H7>J7,"BREACH","OK")) -> OK
A8: EXC-8257 | B8: TX2410049 | C8: FEE_VARIANCE_BREACH | D8: -4.3 | E8: payments-partnerships | F8: 45628 | G8: 45631.991 | H8: 85.78 | I8: =IF(G8="","OPEN","RESOLVED") -> RESOLVED | J8: =IF(C8="TIMING_MISMATCH_TIMEZONE",1,IF(ABS(D8)>5000,4,IF(C8="FEE_VARIANCE_BREACH",120,IF(LEFT(C8,8)="ORPHANED",48,24)))) -> 120 | K8: =IF(H8="","",IF(H8>J8,"BREACH","OK")) -> OK
A9: EXC-8431 | B9: TX2417163 | C9: ORPHANED_GATEWAY_RECORD | D9: 62.04 | E9: finance-ops-recon | F9: 45628 | G9: 45628.573 | H9: 3.75 | I9: =IF(G9="","OPEN","RESOLVED") -> RESOLVED | J9: =IF(C9="TIMING_MISMATCH_TIMEZONE",1,IF(ABS(D9)>5000,4,IF(C9="FEE_VARIANCE_BREACH",120,IF(LEFT(C9,8)="ORPHANED",48,24)))) -> 48 | K9: =IF(H9="","",IF(H9>J9,"BREACH","OK")) -> OK
A10: EXC-8344 | B10: TX2413620 | C10: FEE_VARIANCE_BREACH | D10: -0.9 | E10: payments-partnerships | F10: 45628 | G10: 45632.413 | H10: 95.91 | I10: =IF(G10="","OPEN","RESOLVED") -> RESOLVED | J10: =IF(C10="TIMING_MISMATCH_TIMEZONE",1,IF(ABS(D10)>5000,4,IF(C10="FEE_VARIANCE_BREACH",120,IF(LEFT(C10,8)="ORPHANED",48,24)))) -> 120 | K10: =IF(H10="","",IF(H10>J10,"BREACH","OK")) -> OK
A11: EXC-8376 | B11: TX2414813 | C11: UNCLASSIFIED_VARIANCE | D11: -7.5 | E11: recon-lead | F11: 45628 | G11: 45630.505 | H11: 50.12 | I11: =IF(G11="","OPEN","RESOLVED") -> RESOLVED | J11: =IF(C11="TIMING_MISMATCH_TIMEZONE",1,IF(ABS(D11)>5000,4,IF(C11="FEE_VARIANCE_BREACH",120,IF(LEFT(C11,8)="ORPHANED",48,24)))) -> 24 | K11: =IF(H11="","",IF(H11>J11,"BREACH","OK")) -> BREACH
A12: EXC-8404 | B12: TX2416257 | C12: ORPHANED_GATEWAY_RECORD | D12: 386.39 | E12: finance-ops-recon | F12: 45628 | G12: 45629.343 | H12: 22.22 | I12: =IF(G12="","OPEN","RESOLVED") -> RESOLVED | J12: =IF(C12="TIMING_MISMATCH_TIMEZONE",1,IF(ABS(D12)>5000,4,IF(C12="FEE_VARIANCE_BREACH",120,IF(LEFT(C12,8)="ORPHANED",48,24)))) -> 48 | K12: =IF(H12="","",IF(H12>J12,"BREACH","OK")) -> OK
A13: EXC-8568 | B13: TX2421739 | C13: FEE_VARIANCE_BREACH | D13: -2.05 | E13: payments-partnerships | F13: 45629 | G13: 45632.332 | H13: 69.96 | I13: =IF(G13="","OPEN","RESOLVED") -> RESOLVED | J13: =IF(C13="TIMING_MISMATCH_TIMEZONE",1,IF(ABS(D13)>5000,4,IF(C13="FEE_VARIANCE_BREACH",120,IF(LEFT(C13,8)="ORPHANED",48,24)))) -> 120 | K13: =IF(H13="","",IF(H13>J13,"BREACH","OK")) -> OK
A14: EXC-8565 | B14: TX2421649 | C14: FEE_VARIANCE_BREACH | D14: -0.9 | E14: payments-partnerships | F14: 45629 | G14: 45635.798 | H14: 105.15 | I14: =IF(G14="","OPEN","RESOLVED") -> RESOLVED | J14: =IF(C14="TIMING_MISMATCH_TIMEZONE",1,IF(ABS(D14)>5000,4,IF(C14="FEE_VARIANCE_BREACH",120,IF(LEFT(C14,8)="ORPHANED",48,24)))) -> 120 | K14: =IF(H14="","",IF(H14>J14,"BREACH","OK")) -> OK
A15: EXC-8545 | B15: TX2420759 | C15: FEE_VARIANCE_BREACH | D15: -2.78 | E15: payments-partnerships | F15: 45629 | G15: 45636.208 | H15: 115 | I15: =IF(G15="","OPEN","RESOLVED") -> RESOLVED | J15: =IF(C15="TIMING_MISMATCH_TIMEZONE",1,IF(ABS(D15)>5000,4,IF(C15="FEE_VARIANCE_BREACH",120,IF(LEFT(C15,8)="ORPHANED",48,24)))) -> 120 | K15: =IF(H15="","",IF(H15>J15,"BREACH","OK")) -> OK
... A605: EXC-8500 | B605: TX2419368 | C605: TIMING_MISMATCH_TIMEZONE | D605: 0 | E605: finance-ops-recon | F605: 45656 | G605: 45656.426 | H605: 0.22 | I605: =IF(G605="","OPEN","RESOLVED") -> RESOLVED | J605: =IF(C605="TIMING_MISMATCH_TIMEZONE",1,IF(ABS(D605)>5000,4,IF(C605="FEE_VARIANCE_BREACH",120,IF(LEFT(C605,8)="ORPHANED",48,24)))) -> 1 | K605: =IF(H605="","",IF(H605>J605,"BREACH","OK")) -> OK
A606: EXC-8384 | B606: TX2415490 | C606: FEE_VARIANCE_BREACH | D606: -14.03 | E606: payments-partnerships | F606: 45656 | I606: =IF(G606="","OPEN","RESOLVED") -> OPEN | J606: =IF(C606="TIMING_MISMATCH_TIMEZONE",1,IF(ABS(D606)>5000,4,IF(C606="FEE_VARIANCE_BREACH",120,IF(LEFT(C606,8)="ORPHANED",48,24)))) -> 120 | K606: =IF(H606="","",IF(H606>J606,"BREACH","OK"))
A607: EXC-8069 | B607: TX2403089 | C607: TIMING_MISMATCH_TIMEZONE | D607: 0 | E607: finance-ops-recon | F607: 45656 | G607: 45656.425 | H607: 0.2 | I607: =IF(G607="","OPEN","RESOLVED") -> RESOLVED | J607: =IF(C607="TIMING_MISMATCH_TIMEZONE",1,IF(ABS(D607)>5000,4,IF(C607="FEE_VARIANCE_BREACH",120,IF(LEFT(C607,8)="ORPHANED",48,24)))) -> 1 | K607: =IF(H607="","",IF(H607>J607,"BREACH","OK")) -> OK
A608: EXC-8277 | B608: TX2410581 | C608: TIMING_MISMATCH_TIMEZONE | D608: 0 | E608: finance-ops-recon | F608: 45656 | G608: 45656.429 | H608: 0.31 | I608: =IF(G608="","OPEN","RESOLVED") -> RESOLVED | J608: =IF(C608="TIMING_MISMATCH_TIMEZONE",1,IF(ABS(D608)>5000,4,IF(C608="FEE_VARIANCE_BREACH",120,IF(LEFT(C608,8)="ORPHANED",48,24)))) -> 1 | K608: =IF(H608="","",IF(H608>J608,"BREACH","OK")) -> OK
A609: EXC-8169 | B609: TX2406871 | C609: TIMING_MISMATCH_TIMEZONE | D609: 0 | E609: finance-ops-recon | F609: 45656 | G609: 45656.427 | H609: 0.24 | I609: =IF(G609="","OPEN","RESOLVED") -> RESOLVED | J609: =IF(C609="TIMING_MISMATCH_TIMEZONE",1,IF(ABS(D609)>5000,4,IF(C609="FEE_VARIANCE_BREACH",120,IF(LEFT(C609,8)="ORPHANED",48,24)))) -> 1 | K609: =IF(H609="","",IF(H609>J609,"BREACH","OK")) -> OK
A610: EXC-8564 | B610: TX2421474 | C610: TIMING_MISMATCH_TIMEZONE | D610: 0 | E610: finance-ops-recon | F610: 45656 | G610: 45656.421 | H610: 0.11 | I610: =IF(G610="","OPEN","RESOLVED") -> RESOLVED | J610: =IF(C610="TIMING_MISMATCH_TIMEZONE",1,IF(ABS(D610)>5000,4,IF(C610="FEE_VARIANCE_BREACH",120,IF(LEFT(C610,8)="ORPHANED",48,24)))) -> 1 | K610: =IF(H610="","",IF(H610>J610,"BREACH","OK")) -> OK
A611: EXC-8286 | B611: TX2410921 | C611: UNCLASSIFIED_VARIANCE | D611: -3 | E611: recon-lead | F611: 45656 | G611: 45658.116 | H611: 40.8 | I611: =IF(G611="","OPEN","RESOLVED") -> RESOLVED | J611: =IF(C611="TIMING_MISMATCH_TIMEZONE",1,IF(ABS(D611)>5000,4,IF(C611="FEE_VARIANCE_BREACH",120,IF(LEFT(C611,8)="ORPHANED",48,24)))) -> 24 | K611: =IF(H611="","",IF(H611>J611,"BREACH","OK")) -> BREACH
A612: EXC-8288 | B612: TX2411063 | C612: TIMING_MISMATCH_TIMEZONE | D612: 0 | E612: finance-ops-recon | F612: 45656 | G612: 45656.426 | H612: 0.21 | I612: =IF(G612="","OPEN","RESOLVED") -> RESOLVED | J612: =IF(C612="TIMING_MISMATCH_TIMEZONE",1,IF(ABS(D612)>5000,4,IF(C612="FEE_VARIANCE_BREACH",120,IF(LEFT(C612,8)="ORPHANED",48,24)))) -> 1 | K612: =IF(H612="","",IF(H612>J612,"BREACH","OK")) -> OK
A613: EXC-8375 | B613: TX2414798 | C613: TIMING_MISMATCH_TIMEZONE | D613: 0 | E613: finance-ops-recon | F613: 45656 | G613: 45656.427 | H613: 0.26 | I613: =IF(G613="","OPEN","RESOLVED") -> RESOLVED | J613: =IF(C613="TIMING_MISMATCH_TIMEZONE",1,IF(ABS(D613)>5000,4,IF(C613="FEE_VARIANCE_BREACH",120,IF(LEFT(C613,8)="ORPHANED",48,24)))) -> 1 | K613: =IF(H613="","",IF(H613>J613,"BREACH","OK")) -> OK
A614: EXC-8547 | B614: TX2420806 | C614: FEE_VARIANCE_BREACH | D614: -0.74 | E614: payments-partnerships | F614: 45656 | G614: 45659.5 | H614: 74 | I614: =IF(G614="","OPEN","RESOLVED") -> RESOLVED | J614: =IF(C614="TIMING_MISMATCH_TIMEZONE",1,IF(ABS(D614)>5000,4,IF(C614="FEE_VARIANCE_BREACH",120,IF(LEFT(C614,8)="ORPHANED",48,24)))) -> 120 | K614: =IF(H614="","",IF(H614>J614,"BREACH","OK")) -> OK
A615: EXC-8092 | B615: TX2404097 | C615: TIMING_MISMATCH_TIMEZONE | D615: 0 | E615: finance-ops-recon | F615: 45656 | G615: 45656.425 | H615: 0.2 | I615: =IF(G615="","OPEN","RESOLVED") -> RESOLVED | J615: =IF(C615="TIMING_MISMATCH_TIMEZONE",1,IF(ABS(D615)>5000,4,IF(C615="FEE_VARIANCE_BREACH",120,IF(LEFT(C615,8)="ORPHANED",48,24)))) -> 1 | K615: =IF(H615="","",IF(H615>J615,"BREACH","OK")) -> OK
A616: EXC-8544 | B616: TX2420734 | C616: FEE_VARIANCE_BREACH | D616: -2.37 | E616: payments-partnerships | F616: 45656 | G616: 45659.894 | H616: 83.47 | I616: =IF(G616="","OPEN","RESOLVED") -> RESOLVED | J616: =IF(C616="TIMING_MISMATCH_TIMEZONE",1,IF(ABS(D616)>5000,4,IF(C616="FEE_VARIANCE_BREACH",120,IF(LEFT(C616,8)="ORPHANED",48,24)))) -> 120 | K616: =IF(H616="","",IF(H616>J616,"BREACH","OK")) -> OK
A617: EXC-8534 | B617: TX2420319 | C617: ORPHANED_GATEWAY_RECORD | D617: 53.17 | E617: finance-ops-recon | F617: 45656 | G617: 45658.352 | H617: 46.45 | I617: =IF(G617="","OPEN","RESOLVED") -> RESOLVED | J617: =IF(C617="TIMING_MISMATCH_TIMEZONE",1,IF(ABS(D617)>5000,4,IF(C617="FEE_VARIANCE_BREACH",120,IF(LEFT(C617,8)="ORPHANED",48,24)))) -> 48 | K617: =IF(H617="","",IF(H617>J617,"BREACH","OK")) -> OK
A618: EXC-8358 | B618: TX2414106 | C618: TIMING_MISMATCH_TIMEZONE | D618: 0 | E618: finance-ops-recon | F618: 45656 | G618: 45656.426 | H618: 0.23 | I618: =IF(G618="","OPEN","RESOLVED") -> RESOLVED | J618: =IF(C618="TIMING_MISMATCH_TIMEZONE",1,IF(ABS(D618)>5000,4,IF(C618="FEE_VARIANCE_BREACH",120,IF(LEFT(C618,8)="ORPHANED",48,24)))) -> 1 | K618: =IF(H618="","",IF(H618>J618,"BREACH","OK")) -> OK
... A625: EXC-8174 | B625: TX2406994 | C625: FEE_VARIANCE_BREACH | D625: -1.45 | E625: payments-partnerships | F625: 45657 | G625: 45659.37 | H625: 46.89 | I625: =IF(G625="","OPEN","RESOLVED") -> RESOLVED | J625: =IF(C625="TIMING_MISMATCH_TIMEZONE",1,IF(ABS(D625)>5000,4,IF(C625="FEE_VARIANCE_BREACH",120,IF(LEFT(C625,8)="ORPHANED",48,24)))) -> 120 | K625: =IF(H625="","",IF(H625>J625,"BREACH","OK")) -> OK
A626: EXC-8442 | B626: TX2417631 | C626: FEE_VARIANCE_BREACH | D626: -2.68 | E626: payments-partnerships | F626: 45657 | I626: =IF(G626="","OPEN","RESOLVED") -> OPEN | J626: =IF(C626="TIMING_MISMATCH_TIMEZONE",1,IF(ABS(D626)>5000,4,IF(C626="FEE_VARIANCE_BREACH",120,IF(LEFT(C626,8)="ORPHANED",48,24)))) -> 120 | K626: =IF(H626="","",IF(H626>J626,"BREACH","OK"))
A627: EXC-8560 | B627: TX2421392 | C627: ORPHANED_GATEWAY_RECORD | D627: 553.14 | E627: finance-ops-recon | F627: 45657 | G627: 45658.088 | H627: 16.1 | I627: =IF(G627="","OPEN","RESOLVED") -> RESOLVED | J627: =IF(C627="TIMING_MISMATCH_TIMEZONE",1,IF(ABS(D627)>5000,4,IF(C627="FEE_VARIANCE_BREACH",120,IF(LEFT(C627,8)="ORPHANED",48,24)))) -> 48 | K627: =IF(H627="","",IF(H627>J627,"BREACH","OK")) -> OK
A628: EXC-8399 | B628: TX2416092 | C628: TIMING_MISMATCH_TIMEZONE | D628: 0 | E628: finance-ops-recon | F628: 45657 | G628: 45657.427 | H628: 0.25 | I628: =IF(G628="","OPEN","RESOLVED") -> RESOLVED | J628: =IF(C628="TIMING_MISMATCH_TIMEZONE",1,IF(ABS(D628)>5000,4,IF(C628="FEE_VARIANCE_BREACH",120,IF(LEFT(C628,8)="ORPHANED",48,24)))) -> 1 | K628: =IF(H628="","",IF(H628>J628,"BREACH","OK")) -> OK
A629: EXC-8508 | B629: TX2419582 | C629: ORPHANED_GATEWAY_RECORD | D629: 58.02 | E629: finance-ops-recon | F629: 45657 | G629: 45658.826 | H629: 33.82 | I629: =IF(G629="","OPEN","RESOLVED") -> RESOLVED | J629: =IF(C629="TIMING_MISMATCH_TIMEZONE",1,IF(ABS(D629)>5000,4,IF(C629="FEE_VARIANCE_BREACH",120,IF(LEFT(C629,8)="ORPHANED",48,24)))) -> 48 | K629: =IF(H629="","",IF(H629>J629,"BREACH","OK")) -> OK
A630: EXC-8095 | B630: TX2404381 | C630: TIMING_MISMATCH_TIMEZONE | D630: 0 | E630: finance-ops-recon | F630: 45657 | G630: 45657.426 | H630: 0.22 | I630: =IF(G630="","OPEN","RESOLVED") -> RESOLVED | J630: =IF(C630="TIMING_MISMATCH_TIMEZONE",1,IF(ABS(D630)>5000,4,IF(C630="FEE_VARIANCE_BREACH",120,IF(LEFT(C630,8)="ORPHANED",48,24)))) -> 1 | K630: =IF(H630="","",IF(H630>J630,"BREACH","OK")) -> OK
A631: EXC-8269 | B631: TX2410340 | C631: TIMING_MISMATCH_TIMEZONE | D631: 0 | E631: finance-ops-recon | F631: 45657 | G631: 45657.425 | H631: 0.2 | I631: =IF(G631="","OPEN","RESOLVED") -> RESOLVED | J631: =IF(C631="TIMING_MISMATCH_TIMEZONE",1,IF(ABS(D631)>5000,4,IF(C631="FEE_VARIANCE_BREACH",120,IF(LEFT(C631,8)="ORPHANED",48,24)))) -> 1 | K631: =IF(H631="","",IF(H631>J631,"BREACH","OK")) -> OK
A632: EXC-8395 | B632: TX2415990 | C632: TIMING_MISMATCH_TIMEZONE | D632: 0 | E632: finance-ops-recon | F632: 45657 | G632: 45657.425 | H632: 0.19 | I632: =IF(G632="","OPEN","RESOLVED") -> RESOLVED | J632: =IF(C632="TIMING_MISMATCH_TIMEZONE",1,IF(ABS(D632)>5000,4,IF(C632="FEE_VARIANCE_BREACH",120,IF(LEFT(C632,8)="ORPHANED",48,24)))) -> 1 | K632: =IF(H632="","",IF(H632>J632,"BREACH","OK")) -> OK
A633: EXC-8051 | B633: TX2402410 | C633: TIMING_MISMATCH_TIMEZONE | D633: 0 | E633: finance-ops-recon | F633: 45657 | G633: 45657.419 | H633: 0.06 | I633: =IF(G633="","OPEN","RESOLVED") -> RESOLVED | J633: =IF(C633="TIMING_MISMATCH_TIMEZONE",1,IF(ABS(D633)>5000,4,IF(C633="FEE_VARIANCE_BREACH",120,IF(LEFT(C633,8)="ORPHANED",48,24)))) -> 1 | K633: =IF(H633="","",IF(H633>J633,"BREACH","OK")) -> OK
A634: EXC-8398 | B634: TX2416071 | C634: TIMING_MISMATCH_TIMEZONE | D634: 0 | E634: finance-ops-recon | F634: 45657 | G634: 45657.429 | H634: 0.29 | I634: =IF(G634="","OPEN","RESOLVED") -> RESOLVED | J634: =IF(C634="TIMING_MISMATCH_TIMEZONE",1,IF(ABS(D634)>5000,4,IF(C634="FEE_VARIANCE_BREACH",120,IF(LEFT(C634,8)="ORPHANED",48,24)))) -> 1 | K634: =IF(H634="","",IF(H634>J634,"BREACH","OK")) -> OK
A635: EXC-8037 | B635: TX2401701 | C635: TIMING_MISMATCH_TIMEZONE | D635: 0 | E635: finance-ops-recon | F635: 45657 | G635: 45657.421 | H635: 0.1 | I635: =IF(G635="","OPEN","RESOLVED") -> RESOLVED | J635: =IF(C635="TIMING_MISMATCH_TIMEZONE",1,IF(ABS(D635)>5000,4,IF(C635="FEE_VARIANCE_BREACH",120,IF(LEFT(C635,8)="ORPHANED",48,24)))) -> 1 | K635: =IF(H635="","",IF(H635>J635,"BREACH","OK")) -> OK
A636: EXC-8229 | B636: TX2409072 | C636: TIMING_MISMATCH_TIMEZONE | D636: 0 | E636: finance-ops-recon | F636: 45657 | G636: 45657.426 | H636: 0.23 | I636: =IF(G636="","OPEN","RESOLVED") -> RESOLVED | J636: =IF(C636="TIMING_MISMATCH_TIMEZONE",1,IF(ABS(D636)>5000,4,IF(C636="FEE_VARIANCE_BREACH",120,IF(LEFT(C636,8)="ORPHANED",48,24)))) -> 1 | K636: =IF(H636="","",IF(H636>J636,"BREACH","OK")) -> OK
...

Sheet KPI Tracker
A1: KPI | B1: Value | C1: Definition / note
A2: Total settlements reconciled (Dec 2024) | B2: 26000 | C2: Input from reconciliation run
A3: Exceptions raised | B3: =COUNTA('Exception Tracker'!$A$4:$A$683) -> 680
A4: Matched without exception | B4: =B2-B3 -> 25320
A5: Match rate | B5: =B4/B2 -> 0.97384615 | C5: Matched / total
A6: Exceptions resolved | B6: =COUNTIF('Exception Tracker'!$I$4:$I$683,"RESOLVED") -> 672
A7: Exceptions still open | B7: =COUNTIF('Exception Tracker'!$I$4:$I$683,"OPEN") -> 8
A8: Median clearance velocity (working hours) | B8: =MEDIAN('Exception Tracker'!$H$4:$H$683) -> 0.32 | C8: Weekends excluded
A9: Fee-variance exceptions | B9: =COUNTIF('Exception Tracker'!$C$4:$C$683,"FEE_VARIANCE_BREACH") -> 152 | C9: Count; median by flag is on the dashboard
A10: SLA breaches | B10: =COUNTIF('Exception Tracker'!$K$4:$K$683,"BREACH") -> 65
A11: SLA breach rate (of resolved) | B11: =B10/B6 -> 0.09672619
A12: Net variance across exceptions (AED) | B12: =SUM('Exception Tracker'!$D$4:$D$683) -> 11697.99
A13: Absolute variance across exceptions (AED) | B13: =SUMPRODUCT(ABS('Exception Tracker'!$D$4:$D$683)) -> 44643.29
A18: Exceptions by flag
A19: TIMING_MISMATCH_TIMEZONE | B19: =COUNTIF('Exception Tracker'!$C$4:$C$683,A19) -> 385
A20: FEE_VARIANCE_BREACH | B20: =COUNTIF('Exception Tracker'!$C$4:$C$683,A20) -> 152
A21: ORPHANED_GATEWAY_RECORD | B21: =COUNTIF('Exception Tracker'!$C$4:$C$683,A21) -> 72
A22: ORPHANED_LEDGER_RECORD | B22: =COUNTIF('Exception Tracker'!$C$4:$C$683,A22) -> 48
A23: UNCLASSIFIED_VARIANCE | B23: =COUNTIF('Exception Tracker'!$C$4:$C$683,A23) -> 23
